<?xml version="1.0"?>

<robot name="robot" xmlns:xacro="http://www.ros.org/wiki/xacro">

    <xacro:property name="length_wheel" value="0.05" />
    <xacro:property name="radius_wheel" value="0.06" />
    <xacro:property name="PI" value="3.1415926"/>
    <xacro:macro name="default_inertial" params="mass">
        <inertial>
            <mass value="${mass}" />
            <inertia ixx="0.01" ixy="0.0" ixz="0.0"
                    iyy="0.01" iyz="0.0" izz="0.01" />
        </inertial>
    </xacro:macro>

    <link name="base_link">
        <visual>
            <geometry>
                <box size="0.2 .3 .1"/>
            </geometry>
            <origin rpy="0 0 ${PI/2}" xyz="0 0 0.05"/>  
            <material name="white">
                <color rgba="1 1 1 1"/>
            </material>
        </visual>
        <collision>
            <geometry>
                <box size="0.2 .3 0.1"/>
            </geometry>
        </collision>
        <xacro:default_inertial mass="2.2"/>    
    </link>

    <link name="wheel_1">
        <visual>
            <geometry>
                <cylinder length="${length_wheel}" radius="${radius_wheel}"/>
            </geometry>
            <origin rpy="0 0 0" xyz="0 0 0"/>
            <material name="black">
                <color rgba="0 0 0 1"/>
            </material>
        </visual>
        <collision>
            <geometry>
                <cylinder length="${length_wheel}" radius="${radius_wheel}"/>
            </geometry>
        </collision>
        <mu1>0.5</mu1>
        <mu2>0.5</mu2>
        <xacro:default_inertial mass="0.5"/>  
    </link>

    <link name="wheel_2">
        <visual>
            <geometry>
                <cylinder length="${length_wheel}" radius="${radius_wheel}"/>
            </geometry>
            <origin rpy="0 0 0" xyz="0 0 0"/>
            <material name="black"/>
        </visual>
        <collision>
            <geometry>
                <cylinder length="${length_wheel}" radius="${radius_wheel}"/>
            </geometry>
        </collision>
        <mu1>0.5</mu1>
        <mu2>0.5</mu2>
        <xacro:default_inertial mass="0.5"/>  
    </link>

    <link name="wheel_3">
        <visual>
            <geometry>
                <cylinder length="${length_wheel}" radius="${radius_wheel}"/>
            </geometry>
            <origin rpy="0 0 0" xyz="0 0 0"/>
            <material name="black"/>
        </visual>
        <collision>
            <geometry>
                <cylinder length="${length_wheel}" radius="${radius_wheel}"/>
            </geometry>
        </collision>
        <mu1>0.5</mu1>
        <mu2>0.5</mu2>
        <xacro:default_inertial mass="0.5"/>    
    </link>

    <link name="wheel_4">
        <visual>
            <geometry>
                <cylinder length="${length_wheel}" radius="${radius_wheel}"/>
            </geometry>
            <origin rpy="0 0 0" xyz="0 0 0" />
            <material name="black"/>
        </visual>
        <collision>
            <geometry>
                <cylinder length="${length_wheel}" radius="${radius_wheel}"/>
            </geometry>
        </collision>
        <mu1>0.5</mu1>
        <mu2>0.5</mu2>
        <xacro:default_inertial mass="0.5"/>    
    </link>

    <joint name="base_to_wheel1" type="continuous">
        <parent link="base_link"/>
        <child link="wheel_1"/>
        <origin rpy="${-PI/2} 0 0" xyz="0.1 0.13 0"/>
        <axis xyz="0 0 1" />
    </joint>

    <joint name="base_to_wheel2" type="continuous">
        <axis xyz="0 0 1" />
        <anchor xyz="0 0 0" />
        <limit effort="100" velocity="100" />
        <parent link="base_link"/>
        <child link="wheel_2"/>
        <origin rpy="${-PI/2} 0 0" xyz="-0.1 0.13 0"/>
    </joint>

    <joint name="base_to_wheel3" type="continuous">
        <parent link="base_link"/>
        <axis xyz="0 0 1" />
        <child link="wheel_3"/>
        <origin rpy="${-PI/2} 0 0" xyz="0.1 -0.13 0"/>
    </joint>

    <joint name="base_to_wheel4" type="continuous">
        <parent link="base_link"/>
        <axis xyz="0 0 1" />
        <child link="wheel_4"/>
        <origin rpy="${-PI/2} 0 0" xyz="-0.1 -0.13 0"/>
    </joint>

    <!-- IMU joint -->
    <joint name="imu_joint" type="fixed">
        <axis xyz="0 1 0" />
        <origin xyz="0 0 0.125" rpy="0 0 0"/>
        <parent link="base_link"/>
        <child link="imu_link"/>
    </joint>

    <!-- IMU -->
    <link name="imu_link">
        <collision>
            <origin xyz="0 0 0" rpy="0 0 0"/>
            <geometry>
                <box size="0.05 0.05 0.05"/>
            </geometry>
        </collision>

        <visual>
            <origin xyz="0 0 0" rpy="0 0 0"/>
            <geometry>
                <box size="0.05 0.05 0.05"/>
            </geometry>
            <material name="green">
                <color rgba="0 1 0 1"/>
            </material>
        </visual>

        <inertial>
            <mass value="1e-2" />
            <origin xyz="0 0 0" rpy="0 0 0"/>
            <inertia ixx="1e-6" ixy="0" ixz="0" iyy="1e-6" iyz="0" izz="1e-6" />
        </inertial>
    </link>

    <link name="base_footprint"/>
    <joint name="base_joint" type="fixed">
        <parent link="base_footprint"/>
        <child link="base_link"/>
        <origin xyz="0.0 0.0 0" rpy="0 0 0"/>
    </joint>

    <!-- gazebo插件设置相关 -->

    <gazebo reference="base_link">
        <material>Gazebo/Orange</material>
    </gazebo>

    <gazebo reference="wheel_1">
        <material>Gazebo/Red</material>
    </gazebo>

    <gazebo reference="wheel_2">
        <material>Gazebo/Black</material>
    </gazebo>

    <gazebo reference="wheel_3">
        <material>Gazebo/Red</material>
    </gazebo>

    <gazebo reference="wheel_4">
        <material>Gazebo/Black</material>
    </gazebo>


    <!-- Drive controller -->
    <gazebo>
        <plugin name="mecanum_controller" filename="libgazebo_ros_planar_move.so">
            <ros>
                <!-- <namespace>/demo</namespace> -->
                <remapping>cmd_vel:=cmd_vel</remapping>
                <remapping>odom:=odom</remapping>
            </ros>

            <update_rate>100</update_rate>
            <publish_rate>100</publish_rate>

            <!-- 发布odom -->
            <robotBaseFrame>base_footprint</robotBaseFrame>
            <publish_odom>true</publish_odom>
            <publish_odom_tf>true</publish_odom_tf>

            <leftFrontJoint>base_to_wheel1</leftFrontJoint>
            <rightFrontJoint>base_to_wheel3</rightFrontJoint>
            <leftRearJoint>base_to_wheel2</leftRearJoint>
            <rightRearJoint>base_to_wheel4</rightRearJoint>
            <wheelSeparation>0.26</wheelSeparation>
            <wheelDiameter>0.12</wheelDiameter>
        </plugin>
    </gazebo>

    <!-- imu控制 -->
    <gazebo reference="imu_link">
        <material>Gazebo/Orange</material>
        <gravity>true</gravity>
        <sensor name="imu_sensor" type="imu">
            <always_on>true</always_on>
            <update_rate>100</update_rate>
            <visualize>true</visualize>
            <topic>__default_topic__</topic>
            <plugin filename="libgazebo_ros_imu_sensor.so" name="imu_plugin">
                <!-- <topicName>/livox/imu</topicName> -->
                <topicName>/imu</topicName>
                <bodyName>imu_link</bodyName>
                <updateRateHZ>100.0</updateRateHZ>
                <gaussianNoise>0.0</gaussianNoise>
                <xyzOffset>0 0 0</xyzOffset>
                <rpyOffset>0 0 0</rpyOffset>
                <frameName>imu_link</frameName>
                <serviceName>default_service</serviceName>
                <alwaysOn>true</alwaysOn>
                <maxAngularVelocity>100.0</maxAngularVelocity>
                <noiseDensity>0.0</noiseDensity>
                <randomWalk>0.0</randomWalk>
                <!-- <ros>
                    <remapping>~/out:=/livox/imu</remapping>
                </ros> -->
            </plugin>
        </sensor>
    </gazebo>

    <!-- Livox-Mid360  -->
    <!-- <xacro:include filename="$(find ros2_livox_simulation)/urdf/mid360.xacro" />
    <xacro:mid360 name="livox_frame" parent="base_link" topic="/livox/lidar">
        <origin xyz="0 0.0 0.675" rpy="${PI} 0 0"/>
    </xacro:mid360> -->

    <!-- Livox-Avia -->
    <!-- <xacro:include filename="$(find ros2_livox_simulation)/urdf/avia.xacro" />
    <xacro:avia name="livox" parent="base_link" topic="avia">
        <origin xyz="0 0.0 0.175" rpy="0 0 0"/>
    </xacro:avia> -->

    <!-- Livox-Avia -->
    <joint name="laser_joint" type="fixed">
        <parent link="base_link" />
        <child link="laser_link" />
        <origin xyz="0 0 0.175" />
    </joint>
    <link name="laser_link">
      <visual>
        <origin xyz="0 0 0" rpy="0 0 0"/>
        <geometry>
            <cylinder length="0.02" radius="0.02"/>
        </geometry>
        <material name="black">
            <color rgba="0.0 0.0 0.0 0.8" /> 
        </material>
      </visual>
    </link>
    <gazebo reference="laser_link">
      <sensor name="laser_sensor" type="ray">
      <always_on>true</always_on>
      <visualize>false</visualize>
      <update_rate>10</update_rate>
      <pose>0 0 0 0 0 0</pose>
      <ray>
          <scan>
            <horizontal>
              <samples>360</samples>
              <resolution>1.000000</resolution>
              <min_angle>0.000000</min_angle>
              <max_angle>6.280000</max_angle>
            </horizontal>
          </scan>
          <range>
            <min>0.120000</min>
            <max>8</max>
            <resolution>0.015000</resolution>
          </range>
          <noise>
            <type>gaussian</type>
            <mean>0.0</mean>
            <stddev>0.01</stddev>
          </noise>
      </ray>
      <plugin name="laserscan" filename="libgazebo_ros_ray_sensor.so">
        <ros>
          <remapping>~/out:=scan</remapping>
        </ros>
        <output_type>sensor_msgs/LaserScan</output_type>
        <frame_name>laser_link</frame_name>
      </plugin>
      </sensor>
    </gazebo>

    <joint name="camera_joint" type="fixed">
        <parent link="base_link" />
        <child link="camera_link" />
        <origin xyz="0.1 0 0.2" />
    </joint>
    <link name="camera_link">
      <visual>
        <origin xyz="0 0 0" rpy="0 1.585 0"/>
        <material name="black">
            <color rgba="0.0 0.0 0.0 0.8" /> 
        </material>
        <geometry>
            <cylinder length="0.01" radius="0.01"/>
        </geometry>
      </visual>
    </link>
        <!-- camera -->
    <gazebo reference="camera_link">
        <sensor type="camera" name="camera1">
          <update_rate>30.0</update_rate>
          <camera name="head">
            <horizontal_fov>1.3962634</horizontal_fov>
            <image>
              <width>800</width>
              <height>800</height>
              <format>R8G8B8</format>
            </image>
            <clip>
              <near>0.02</near>
              <far>300</far>
            </clip>
            <noise>
              <type>gaussian</type>
              <!-- Noise is sampled independently per pixel on each frame.
                   That pixel's noise value is added to each of its color
                   channels, which at that point lie in the range [0,1]. -->
              <mean>0.0</mean>
              <stddev>0.007</stddev>
            </noise>
          </camera>
          <plugin name="camera_controller" filename="libgazebo_ros_camera.so">
            <alwaysOn>true</alwaysOn>
            <updateRate>0.0</updateRate>
            <cameraName>/camera1</cameraName>
            <imageTopicName>image_raw</imageTopicName>
            <cameraInfoTopicName>camera_info</cameraInfoTopicName>
            <frameName>camera_link</frameName>
            <hackBaseline>0.07</hackBaseline>
            <distortionK1>0.0</distortionK1>
            <distortionK2>0.0</distortionK2>
            <distortionK3>0.0</distortionK3>
            <distortionT1>0.0</distortionT1>
            <distortionT2>0.0</distortionT2>
          </plugin>
        </sensor>
    </gazebo>

</robot>
